[2020-11-21 03:39:35,980] ERROR [django.request:224] Internal Server Error: /all_sessions/
Traceback (most recent call last):
  File "/var/www/pacificcontrol.net/venv/lib/python3.8/site-packages/django/core/handlers/exception.py", line 47, in inner
    response = get_response(request)
  File "/var/www/pacificcontrol.net/venv/lib/python3.8/site-packages/django/core/handlers/base.py", line 179, in _get_response
    response = wrapped_callback(request, *callback_args, **callback_kwargs)
  File "/var/www/pacificcontrol.net/zhuartcc/decorators.py", line 31, in inner
    return func(request, *args, **kwargs)
  File "/var/www/pacificcontrol.net/apps/api/views.py", line 38, in all_sessions
    return render(request, 'all_sessions.html', {
  File "/var/www/pacificcontrol.net/venv/lib/python3.8/site-packages/django/shortcuts.py", line 19, in render
    content = loader.render_to_string(template_name, context, request, using=using)
  File "/var/www/pacificcontrol.net/venv/lib/python3.8/site-packages/django/template/loader.py", line 62, in render_to_string
    return template.render(context, request)
  File "/var/www/pacificcontrol.net/venv/lib/python3.8/site-packages/django/template/backends/django.py", line 61, in render
    return self.template.render(context)
  File "/var/www/pacificcontrol.net/venv/lib/python3.8/site-packages/django/template/base.py", line 170, in render
    return self._render(context)
  File "/var/www/pacificcontrol.net/venv/lib/python3.8/site-packages/django/template/base.py", line 162, in _render
    return self.nodelist.render(context)
  File "/var/www/pacificcontrol.net/venv/lib/python3.8/site-packages/django/template/base.py", line 938, in render
    bit = node.render_annotated(context)
  File "/var/www/pacificcontrol.net/venv/lib/python3.8/site-packages/django/template/base.py", line 905, in render_annotated
    return self.render(context)
  File "/var/www/pacificcontrol.net/venv/lib/python3.8/site-packages/django/template/loader_tags.py", line 150, in render
    return compiled_parent._render(context)
  File "/var/www/pacificcontrol.net/venv/lib/python3.8/site-packages/django/template/base.py", line 162, in _render
    return self.nodelist.render(context)
  File "/var/www/pacificcontrol.net/venv/lib/python3.8/site-packages/django/template/base.py", line 938, in render
    bit = node.render_annotated(context)
  File "/var/www/pacificcontrol.net/venv/lib/python3.8/site-packages/django/template/base.py", line 905, in render_annotated
    return self.render(context)
  File "/var/www/pacificcontrol.net/venv/lib/python3.8/site-packages/django/template/loader_tags.py", line 62, in render
    result = block.nodelist.render(context)
  File "/var/www/pacificcontrol.net/venv/lib/python3.8/site-packages/django/template/base.py", line 938, in render
    bit = node.render_annotated(context)
  File "/var/www/pacificcontrol.net/venv/lib/python3.8/site-packages/django/template/base.py", line 905, in render_annotated
    return self.render(context)
  File "/var/www/pacificcontrol.net/venv/lib/python3.8/site-packages/django/template/defaulttags.py", line 446, in render
    url = reverse(view_name, args=args, kwargs=kwargs, current_app=current_app)
  File "/var/www/pacificcontrol.net/venv/lib/python3.8/site-packages/django/urls/base.py", line 87, in reverse
    return iri_to_uri(resolver._reverse_with_prefix(view, prefix, *args, **kwargs))
  File "/var/www/pacificcontrol.net/venv/lib/python3.8/site-packages/django/urls/resolvers.py", line 685, in _reverse_with_prefix
    raise NoReverseMatch(msg)
django.urls.exceptions.NoReverseMatch: Reverse for 'all_sessions/$/delete' not found. 'all_sessions/$/delete' is not a valid view function or pattern name.
